Workbook

Sheet Info
A1: Расчёт цен для конструктора «Оконика» — рабочий шаблон
A3: Как пользоваться:
A4: 1. Открываете ПО производителя. Собираете окна ТОЧНО как указано на каждом листе.
A5: 2. Вписываете полученную цену в ЖЁЛТЫЕ ячейки. Остальное считается само.
A6: 3. Зелёные ячейки — готовые коэффициенты. Переносите их в src/data/windows.json.
A8: Листы (вкладки внизу):
A9: • Profile (Профиль) — ставки руб/м² для эконом/стандарт/премиум (7 точек + МНК).
A10: • Glass (Стеклопакет) — ставки руб/м² для 1-кам/2-кам/2-кам-энерго.
A11: • Color (Цвет) — множители ламинации.
A12: • Opening (Открывание) — надбавка за створку.
A13: • Hardware (Фурнитура) — надбавка за окно.
A14: • Extras (Допы) — надбавка за штуку.
... A20: Подробный вывод формул — в файле pricing-guide.md рядом.

Sheet Summary
A1: СВОДКА (Summary) — переносите числа в windows.json
A3: Позиция | B3: priceType | C3: Значение (price) | D3: Формула / источник
A4: профиль: Эконом | B4: perM2 | C4: =Profile!E13-(Glass!F13-Glass!E13) -> #VALUE! | D4: a_эконом − стекло_2кам
A5: профиль: Стандарт | B5: perM2 | C5: =Profile!F13-(Glass!F13-Glass!E13) -> #VALUE! | D5: a_стандарт − стекло_2кам
A6: профиль: Премиум | B6: perM2 | C6: =(Profile!F13-(Glass!F13-Glass!E13))+(Profile!G13-Profile!F13) -> #VALUE! | D6: профиль_станд + (a_прем − a_станд)
A7: стекло: 1-камерный | B7: perM2 | C7: =0 -> 0 | D7: принято за базовое
A8: стекло: 2-камерный | B8: perM2 | C8: =Glass!F13-Glass!E13 -> #VALUE! | D8: a_2кам − a_1кам
A9: стекло: 2-кам энерго | B9: perM2 | C9: =Glass!G13-Glass!E13 -> #VALUE! | D9: a_2кам_э − a_1кам
A10: цвет: Белый | B10: multiplier | C10: =Color!E5 -> 1 | D10: эталон = 1
A11: цвет: Серый | B11: multiplier | C11: =Color!E6 -> 1 | D11: P_серый/P_белый
A12: цвет: Золотой дуб | B12: multiplier | C12: =Color!E7 -> 1 | D12: P_дуб/P_белый
A13: цвет: Орех | B13: multiplier | C13: =Color!E8 -> 1 | D13: P_орех/P_белый
A14: цвет: Антрацит | B14: multiplier | C14: =Color!E9 -> 1 | D14: P_антрацит/P_белый
A15: открыв.: Глухое | B15: fixed | C15: =0 -> 0 | D15: нет механизма
A16: открыв.: Откидное | B16: fixed | C16: =Opening!C6 -> 0 | D16: P_T0 − P_00
A17: открыв.: Пов-откидное | B17: fixed | C17: =Opening!C7 -> 0 | D17: P_R0 − P_00
A18: фурнитура: Базовая | B18: fixed | C18: =Hardware!C5 -> 0 | D18: эталон = 0
A19: фурнитура: Комфорт | B19: fixed | C19: =Hardware!C6 -> 0 | D19: P_комф − P_баз
A20: фурнитура: Премиум | B20: fixed | C20: =Hardware!C7 -> 0 | D20: P_прем − P_баз
A21: доп: Москитка | B21: fixed | C21: =Extras!C6 -> 0 | D21: P_опц − P_0
A22: доп: Подоконник+откосы | B22: fixed | C22: =Extras!C7 -> 0 | D22: P_опц − P_0
A23: доп: Монтаж | B23: fixed | C23: =Extras!C8 -> 0 | D23: P_опц − P_0
A24: доп: Вывоз | B24: fixed | C24: =Extras!C9 -> 0 | D24: P_опц − P_0
A25: basePrice: (тип) | B25: — | C25: =Profile!E14 -> #VALUE! | D25: b (пост. часть) эталонной серии; считать на тип

Sheet Profile
A1: ПРОФИЛЬ (Profile) — ставки руб/м²
A2: Соберите 7 окон каждого профиля. Фикс: стекло 2-камерное, цвет белый, всё глухое, фурнитура базовая, без допов. Меняете ТОЛЬКО профиль.
A4: Серии (впишите цены из ПО в жёлтые ячейки):
A5: № | B5: Ширина, см | C5: Высота, см | D5: Площадь, м² | E5: Эконом, руб | F5: Стандарт, руб | G5: Премиум, руб | I5: base | J5: 2 ctekla | M5: base | N5: 3 ctekla | Q5: base | R5: energo
A6: 1 | B6: 90 | C6: 90 | D6: =B6*C6/10000 -> 0.81 | I6: 100 | J6: 100 | K6: 3850 | M6: 100 | N6: 100 | O6: 4600 | Q6: 100 | R6: 100 | S6: 4900
A7: 2 | B7: 100 | C7: 110 | D7: =B7*C7/10000 -> 1.1 | I7: 100 | J7: 200 | K7: 6500 | M7: 100 | N7: 200 | O7: 7900 | Q7: 100 | R7: 200 | S7: 8600
A8: 3 | B8: 120 | C8: 120 | D8: =B8*C8/10000 -> 1.44 | I8: 150 | J8: 200 | K8: 10900 | M8: 120 | N8: 190 | O8: 8700 | Q8: 120 | R8: 190 | S8: 9500
A9: 4 | B9: 130 | C9: 140 | D9: =B9*C9/10000 -> 1.82
A10: 5 | B10: 150 | C10: 150 | D10: =B10*C10/10000 -> 2.25 | I10: profile m | J10: 2 ctekla | M10: profile m | N10: 3 ctekla | Q10: profile m | R10: energo
A11: 6 | B11: 170 | C11: 160 | D11: =B11*C11/10000 -> 2.72 | I11: 100 | J11: 100 | K11: 4400 | M11: 100 | N11: 100 | O11: 5000 | Q11: 100 | R11: 100 | S11: 5300
A12: 7 | B12: 200 | C12: 150 | D12: =B12*C12/10000 -> 3 | I12: 100 | J12: 200 | K12: 7300 | M12: 100 | N12: 200 | O12: 8600 | Q12: 100 | R12: 200 | S12: 9200
D13: a = руб/м² (наклон) | E13: =SLOPE($E$6:$E$12,$D$6:$D$12) -> #VALUE! | F13: =SLOPE($F$6:$F$12,$D$6:$D$12) -> #VALUE! | G13: =SLOPE($G$6:$G$12,$D$6:$D$12) -> #VALUE! | I13: 150 | J13: 200 | K13: 12000 | M13: 130 | N13: 190 | O13: 12000 | Q13: 130 | R13: 190 | S13: 12800
D14: b = постоянная (руб) | E14: =INTERCEPT($E$6:$E$12,$D$6:$D$12) -> #VALUE! | F14: =INTERCEPT($F$6:$F$12,$D$6:$D$12) -> #VALUE! | G14: =INTERCEPT($G$6:$G$12,$D$6:$D$12) -> #VALUE!
M15: profile l | N15: 3 ctekla | Q15: profile l | R15: energo
M16: 100 | N16: 100 | O16: 6500 | Q16: 100 | R16: 100 | S16: 7000
M17: 100 | N17: 200 | O17: 10500 | Q17: 100 | R17: 200 | S17: 11800
C18: 1 | D18: 50 50 | E18: 60 60 | F18: 100200 | M18: 150 | N18: 200 | O18: 16500 | Q18: 150 | R18: 200 | S18: 18500
C19: 2 | E19: 90 65 | F19: 200200
C20: 3 | E20: 135 65 | F20: 250180 | I20: otkrivnoe | J20: 2 ctekla | K20: furnit s | M20: otkrivnoe | N20: 3 ctekla | O20: furnit s | Q20: otkrivnoe | R20: energo | S20: furnit s
I21: 100 | J21: 100 | K21: 8600 | M21: 100 | N21: 100 | O21: 9300 | Q21: 100 | R21: 100 | S21: 9500
I22: 100 | J22: 200 | K22: 13000 | M22: 100 | N22: 200 | O22: 14200 | Q22: 100 | R22: 200 | S22: 14800
I23: 120 | J23: 200 | K23: 14000 | M23: 120 | N23: 200 | O23: 15500 | Q23: 120 | R23: 200 | S23: 16200
M25: profile m | N25: 3 ctekla | O25: furnit s | Q25: profile m | R25: energo | S25: furnit s
M26: 100 | N26: 100 | O26: 10100 | Q26: 100 | R26: 100 | S26: 10400
M27: 100 | N27: 200 | O27: 15500 | Q27: 100 | R27: 200 | S27: 16000
M28: 120 | N28: 200 | O28: 16900 | Q28: 120 | R28: 200 | S28: 17600
Q30: profile m | R30: energo | S30: furnit l
Q31: 100 | R31: 100 | S31: 11300
Q32: 100 | R32: 200 | S32: 17700
Q33: 130 | R33: 200 | S33: 20300
Q35: proile l | R35: energo | S35: furnit l | T35: color
Q36: 100 | R36: 100 | S36: 13600 | T36: 23500
Q37: 100 | R37: 200 | S37: 21100
Q38: 130 | R38: 200 | S38: 24300
I40: 2 ctvorki base | J40: 2 ctekla | M40: 2 ctvorki base | N40: 3 ctekla | Q40: 2 ctvorki base | R40: energo
I41: 100 | J41: 100 | K41: 5000 | M41: 100 | N41: 100 | O41: 5900 | Q41: 100 | R41: 100 | S41: 6200
I42: 100 | J42: 200 | K42: 8300 | M42: 100 | N42: 200 | O42: 9800 | Q42: 100 | R42: 200 | S42: 10400
I43: 150 | J43: 200 | K43: 10400 | M43: 150 | N43: 200 | O43: 12700 | Q43: 150 | R43: 200 | S43: 13600
I44: 200 | J44: 150 | K44: 10000 | M44: 200 | N44: 150 | O44: 12200 | Q44: 200 | R44: 150 | S44: 13200
M46: profile m | N46: 3 ctekla | Q46: profile m | R46: energo
...

Sheet Glass
A1: СТЕКЛОПАКЕТ (Glass) — ставки руб/м²
A2: Соберите 7 окон с каждым стеклом. Фикс: профиль Стандарт, цвет белый, всё глухое, фурнитура базовая, без допов. Меняете ТОЛЬКО стекло.
A4: Серии (впишите цены из ПО в жёлтые ячейки):
A5: № | B5: Ширина, см | C5: Высота, см | D5: Площадь, м² | E5: 1-камерный, руб | F5: 2-камерный, руб | G5: 2-кам энерго, руб
A6: 1 | B6: 90 | C6: 90 | D6: =B6*C6/10000 -> 0.81
A7: 2 | B7: 100 | C7: 110 | D7: =B7*C7/10000 -> 1.1
A8: 3 | B8: 120 | C8: 120 | D8: =B8*C8/10000 -> 1.44
A9: 4 | B9: 130 | C9: 140 | D9: =B9*C9/10000 -> 1.82
A10: 5 | B10: 150 | C10: 150 | D10: =B10*C10/10000 -> 2.25
A11: 6 | B11: 170 | C11: 160 | D11: =B11*C11/10000 -> 2.72
A12: 7 | B12: 200 | C12: 150 | D12: =B12*C12/10000 -> 3
D13: a = руб/м² (наклон) | E13: =SLOPE($E$6:$E$12,$D$6:$D$12) -> #VALUE! | F13: =SLOPE($F$6:$F$12,$D$6:$D$12) -> #VALUE! | G13: =SLOPE($G$6:$G$12,$D$6:$D$12) -> #VALUE!
D14: b = постоянная (руб) | E14: =INTERCEPT($E$6:$E$12,$D$6:$D$12) -> #VALUE! | F14: =INTERCEPT($F$6:$F$12,$D$6:$D$12) -> #VALUE! | G14: =INTERCEPT($G$6:$G$12,$D$6:$D$12) -> #VALUE!

Sheet Color
A1: ЦВЕТ (Color) — множитель ламинации
A2: Одно фикс. окно (напр. 130×140, Стандарт, 2-кам, глухое, базовая, без допов) в каждом цвете. Впишите цену. Для надёжности — 3 разных окна, усредним.
A4: Цвет | B4: Окно 1, руб | C4: Окно 2, руб | D4: Окно 3, руб | E4: Множитель
A5: Белый (эталон) | E5: 1
A6: Серый | E6: =IFERROR(AVERAGE(B6/B5,C6/C5,D6/D5),1) -> 1
A7: Золотой дуб | E7: =IFERROR(AVERAGE(B7/B5,C7/C5,D7/D5),1) -> 1
A8: Орех | E8: =IFERROR(AVERAGE(B8/B5,C8/C5,D8/D5),1) -> 1
A9: Антрацит | E9: =IFERROR(AVERAGE(B9/B5,C9/C5,D9/D5),1) -> 1

Sheet Opening
A1: ОТКРЫВАНИЕ (Opening) — руб за створку
A2: Двухстворчатое, размер фикс. (напр. 130×140), профиль/стекло/цвет базовые. Впишите цены сборок. Проверьте на 3 размерах — надбавка не должна зависеть от размера.
A4: Сборка | B4: Цена из ПО, руб | C4: Надбавка/створку
A5: Обе створки ГЛУХИЕ (P_00) | C5: 0
A6: Одна ОТКИДНАЯ + глухая (P_T0) | C6: =B6-B5 -> 0
A7: Одна ПОВОРОТНО-ОТКИДНАЯ + глухая (P_R0) | C7: =B7-B5 -> 0
A8: Обе ПОВОРОТНО-ОТКИДНЫЕ (P_RR) — проверка | C8: =IF(ABS(B8-(B5+2*C7))<=B5*0.02,"аддитивно OK","проверить!") -> аддитивно OK

Sheet Hardware
A1: ФУРНИТУРА (Hardware) — руб за окно
A2: Фикс. окно, меняете только фурнитуру. Базовая = эталон (0).
A4: Комплект | B4: Цена из ПО, руб | C4: Надбавка, руб
A5: Базовая (эталон) | C5: 0
A6: Комфорт | C6: =B6-B5 -> 0
A7: Премиум | C7: =B7-B5 -> 0

Sheet Extras
A1: ДОП. ОПЦИИ (Extras) — руб за штуку
A2: Базовое окно без опций = P_0. Добавляете по ОДНОЙ опции. Монтаж/подоконник проверьте на 2 размерах (могут зависеть от размера).
A4: Опция | B4: Цена с опцией, руб | C4: Надбавка, руб
A5: Базовое окно (P_0)
A6: Москитная сетка | C6: =B6-B5 -> 0
A7: Подоконник и откосы | C7: =B7-B5 -> 0
A8: Монтаж | C8: =B8-B5 -> 0
A9: Вывоз старого окна | C9: =B9-B5 -> 0
